[2024-12-19T23:50:00.795+0000] {taskinstance.py:1956} INFO - Dependencies all met for dep_context=non-requeueable deps ti=<TaskInstance: data_pipeline.save_to_db manual__2024-12-19T23:49:42.244621+00:00 [queued]>
[2024-12-19T23:50:00.805+0000] {taskinstance.py:1956} INFO - Dependencies all met for dep_context=requeueable deps ti=<TaskInstance: data_pipeline.save_to_db manual__2024-12-19T23:49:42.244621+00:00 [queued]>
[2024-12-19T23:50:00.806+0000] {taskinstance.py:2170} INFO - Starting attempt 1 of 3
[2024-12-19T23:50:00.825+0000] {taskinstance.py:2191} INFO - Executing <Task(PythonOperator): save_to_db> on 2024-12-19 23:49:42.244621+00:00
[2024-12-19T23:50:00.832+0000] {standard_task_runner.py:60} INFO - Started process 24442 to run task
[2024-12-19T23:50:00.835+0000] {standard_task_runner.py:87} INFO - Running: ['***', 'tasks', 'run', 'data_pipeline', 'save_to_db', 'manual__2024-12-19T23:49:42.244621+00:00', '--job-id', '209', '--raw', '--subdir', 'DAGS_FOLDER/data_pipeline_dag.py', '--cfg-path', '/tmp/tmpt3t9yuba']
[2024-12-19T23:50:00.838+0000] {standard_task_runner.py:88} INFO - Job 209: Subtask save_to_db
[2024-12-19T23:50:00.889+0000] {task_command.py:423} INFO - Running <TaskInstance: data_pipeline.save_to_db manual__2024-12-19T23:49:42.244621+00:00 [running]> on host 1d3bd1c7da18
[2024-12-19T23:50:00.977+0000] {taskinstance.py:2480} INFO - Exporting env vars: AIRFLOW_CTX_DAG_OWNER='***' AIRFLOW_CTX_DAG_ID='data_pipeline' AIRFLOW_CTX_TASK_ID='save_to_db' AIRFLOW_CTX_EXECUTION_DATE='2024-12-19T23:49:42.244621+00:00' AIRFLOW_CTX_TRY_NUMBER='1' AIRFLOW_CTX_DAG_RUN_ID='manual__2024-12-19T23:49:42.244621+00:00'
[2024-12-19T23:50:01.126+0000] {taskinstance.py:2698} ERROR - Task failed with exception
Traceback (most recent call last):
  File "/home/airflow/.local/lib/python3.8/site-packages/airflow/models/taskinstance.py", line 433, in _execute_task
    result = execute_callable(context=context, **execute_callable_kwargs)
  File "/home/airflow/.local/lib/python3.8/site-packages/airflow/operators/python.py", line 199, in execute
    return_value = self.execute_callable()
  File "/home/airflow/.local/lib/python3.8/site-packages/airflow/operators/python.py", line 216, in execute_callable
    return self.python_callable(*self.op_args, **self.op_kwargs)
  File "/opt/airflow/dags/data_pipeline_dag.py", line 15, in trigger_api
    raise Exception(f"Error: {result['message']}")
Exception: Error: duplicate key value violates unique constraint "movies_pkey"
DETAIL:  Key (movieid)=(5) already exists.

[2024-12-19T23:50:01.138+0000] {taskinstance.py:1138} INFO - Marking task as UP_FOR_RETRY. dag_id=data_pipeline, task_id=save_to_db, execution_date=20241219T234942, start_date=20241219T235000, end_date=20241219T235001
[2024-12-19T23:50:01.153+0000] {standard_task_runner.py:107} ERROR - Failed to execute job 209 for task save_to_db (Error: duplicate key value violates unique constraint "movies_pkey"
DETAIL:  Key (movieid)=(5) already exists.
; 24442)
[2024-12-19T23:50:01.168+0000] {local_task_job_runner.py:234} INFO - Task exited with return code 1
[2024-12-19T23:50:01.187+0000] {taskinstance.py:3280} INFO - 0 downstream tasks scheduled from follow-on schedule check
