[2024-12-17T08:24:45.532+0000] {taskinstance.py:1956} INFO - Dependencies all met for dep_context=non-requeueable deps ti=<TaskInstance: data_pipeline.data_ingestion manual__2024-12-17T08:24:43.883190+00:00 [queued]>
[2024-12-17T08:24:45.540+0000] {taskinstance.py:1956} INFO - Dependencies all met for dep_context=requeueable deps ti=<TaskInstance: data_pipeline.data_ingestion manual__2024-12-17T08:24:43.883190+00:00 [queued]>
[2024-12-17T08:24:45.541+0000] {taskinstance.py:2170} INFO - Starting attempt 1 of 2
[2024-12-17T08:24:45.562+0000] {taskinstance.py:2191} INFO - Executing <Task(PythonOperator): data_ingestion> on 2024-12-17 08:24:43.883190+00:00
[2024-12-17T08:24:45.568+0000] {standard_task_runner.py:60} INFO - Started process 112 to run task
[2024-12-17T08:24:45.571+0000] {standard_task_runner.py:87} INFO - Running: ['***', 'tasks', 'run', 'data_pipeline', 'data_ingestion', 'manual__2024-12-17T08:24:43.883190+00:00', '--job-id', '35', '--raw', '--subdir', 'DAGS_FOLDER/data_pipeline_dag.py', '--cfg-path', '/tmp/tmpfar5p9py']
[2024-12-17T08:24:45.573+0000] {standard_task_runner.py:88} INFO - Job 35: Subtask data_ingestion
[2024-12-17T08:24:45.622+0000] {task_command.py:423} INFO - Running <TaskInstance: data_pipeline.data_ingestion manual__2024-12-17T08:24:43.883190+00:00 [running]> on host 1d3bd1c7da18
[2024-12-17T08:24:45.697+0000] {taskinstance.py:2480} INFO - Exporting env vars: AIRFLOW_CTX_DAG_OWNER='***' AIRFLOW_CTX_DAG_ID='data_pipeline' AIRFLOW_CTX_TASK_ID='data_ingestion' AIRFLOW_CTX_EXECUTION_DATE='2024-12-17T08:24:43.883190+00:00' AIRFLOW_CTX_TRY_NUMBER='1' AIRFLOW_CTX_DAG_RUN_ID='manual__2024-12-17T08:24:43.883190+00:00'
[2024-12-17T08:24:45.699+0000] {logging_mixin.py:188} INFO - Data ingestion starting
[2024-12-17T08:24:45.700+0000] {taskinstance.py:2698} ERROR - Task failed with exception
Traceback (most recent call last):
  File "/home/airflow/.local/lib/python3.8/site-packages/airflow/models/taskinstance.py", line 433, in _execute_task
    result = execute_callable(context=context, **execute_callable_kwargs)
  File "/home/airflow/.local/lib/python3.8/site-packages/airflow/operators/python.py", line 199, in execute
    return_value = self.execute_callable()
  File "/home/airflow/.local/lib/python3.8/site-packages/airflow/operators/python.py", line 216, in execute_callable
    return self.python_callable(*self.op_args, **self.op_kwargs)
  File "/opt/airflow/dags/data_pipeline_dag.py", line 10, in data_ingestion
    print(os.cwd(), flush = True)
AttributeError: module 'os' has no attribute 'cwd'
[2024-12-17T08:24:45.711+0000] {taskinstance.py:1138} INFO - Marking task as UP_FOR_RETRY. dag_id=data_pipeline, task_id=data_ingestion, execution_date=20241217T082443, start_date=20241217T082445, end_date=20241217T082445
[2024-12-17T08:24:45.724+0000] {standard_task_runner.py:107} ERROR - Failed to execute job 35 for task data_ingestion (module 'os' has no attribute 'cwd'; 112)
[2024-12-17T08:24:45.743+0000] {local_task_job_runner.py:234} INFO - Task exited with return code 1
[2024-12-17T08:24:45.769+0000] {taskinstance.py:3280} INFO - 0 downstream tasks scheduled from follow-on schedule check
