[2024-12-19T22:37:04.993+0000] {taskinstance.py:1956} INFO - Dependencies all met for dep_context=non-requeueable deps ti=<TaskInstance: data_pipeline.data_processing_structured manual__2024-12-19T22:37:01.139025+00:00 [queued]>
[2024-12-19T22:37:05.005+0000] {taskinstance.py:1956} INFO - Dependencies all met for dep_context=requeueable deps ti=<TaskInstance: data_pipeline.data_processing_structured manual__2024-12-19T22:37:01.139025+00:00 [queued]>
[2024-12-19T22:37:05.005+0000] {taskinstance.py:2170} INFO - Starting attempt 1 of 3
[2024-12-19T22:37:05.024+0000] {taskinstance.py:2191} INFO - Executing <Task(PythonOperator): data_processing_structured> on 2024-12-19 22:37:01.139025+00:00
[2024-12-19T22:37:05.031+0000] {standard_task_runner.py:60} INFO - Started process 23249 to run task
[2024-12-19T22:37:05.034+0000] {standard_task_runner.py:87} INFO - Running: ['***', 'tasks', 'run', 'data_pipeline', 'data_processing_structured', 'manual__2024-12-19T22:37:01.139025+00:00', '--job-id', '170', '--raw', '--subdir', 'DAGS_FOLDER/data_pipeline_dag.py', '--cfg-path', '/tmp/tmp85dknfsj']
[2024-12-19T22:37:05.037+0000] {standard_task_runner.py:88} INFO - Job 170: Subtask data_processing_structured
[2024-12-19T22:37:05.090+0000] {task_command.py:423} INFO - Running <TaskInstance: data_pipeline.data_processing_structured manual__2024-12-19T22:37:01.139025+00:00 [running]> on host 1d3bd1c7da18
[2024-12-19T22:37:05.171+0000] {taskinstance.py:2480} INFO - Exporting env vars: AIRFLOW_CTX_DAG_OWNER='***' AIRFLOW_CTX_DAG_ID='data_pipeline' AIRFLOW_CTX_TASK_ID='data_processing_structured' AIRFLOW_CTX_EXECUTION_DATE='2024-12-19T22:37:01.139025+00:00' AIRFLOW_CTX_TRY_NUMBER='1' AIRFLOW_CTX_DAG_RUN_ID='manual__2024-12-19T22:37:01.139025+00:00'
[2024-12-19T22:37:10.330+0000] {taskinstance.py:2698} ERROR - Task failed with exception
Traceback (most recent call last):
  File "/home/airflow/.local/lib/python3.8/site-packages/airflow/models/taskinstance.py", line 433, in _execute_task
    result = execute_callable(context=context, **execute_callable_kwargs)
  File "/home/airflow/.local/lib/python3.8/site-packages/airflow/operators/python.py", line 199, in execute
    return_value = self.execute_callable()
  File "/home/airflow/.local/lib/python3.8/site-packages/airflow/operators/python.py", line 216, in execute_callable
    return self.python_callable(*self.op_args, **self.op_kwargs)
  File "/opt/airflow/dags/data_pipeline_dag.py", line 15, in trigger_api
    raise Exception(f"Error: {result['message']}")
Exception: Error: name 'spark' is not defined
[2024-12-19T22:37:10.342+0000] {taskinstance.py:1138} INFO - Marking task as UP_FOR_RETRY. dag_id=data_pipeline, task_id=data_processing_structured, execution_date=20241219T223701, start_date=20241219T223704, end_date=20241219T223710
[2024-12-19T22:37:10.361+0000] {standard_task_runner.py:107} ERROR - Failed to execute job 170 for task data_processing_structured (Error: name 'spark' is not defined; 23249)
[2024-12-19T22:37:10.393+0000] {local_task_job_runner.py:234} INFO - Task exited with return code 1
[2024-12-19T22:37:10.417+0000] {taskinstance.py:3280} INFO - 0 downstream tasks scheduled from follow-on schedule check
