[2024-12-19T22:56:30.912+0000] {taskinstance.py:1956} INFO - Dependencies all met for dep_context=non-requeueable deps ti=<TaskInstance: data_pipeline.data_processing_structured manual__2024-12-19T22:56:27.030091+00:00 [queued]>
[2024-12-19T22:56:30.921+0000] {taskinstance.py:1956} INFO - Dependencies all met for dep_context=requeueable deps ti=<TaskInstance: data_pipeline.data_processing_structured manual__2024-12-19T22:56:27.030091+00:00 [queued]>
[2024-12-19T22:56:30.922+0000] {taskinstance.py:2170} INFO - Starting attempt 1 of 3
[2024-12-19T22:56:30.937+0000] {taskinstance.py:2191} INFO - Executing <Task(PythonOperator): data_processing_structured> on 2024-12-19 22:56:27.030091+00:00
[2024-12-19T22:56:30.943+0000] {standard_task_runner.py:60} INFO - Started process 23602 to run task
[2024-12-19T22:56:30.946+0000] {standard_task_runner.py:87} INFO - Running: ['***', 'tasks', 'run', 'data_pipeline', 'data_processing_structured', 'manual__2024-12-19T22:56:27.030091+00:00', '--job-id', '191', '--raw', '--subdir', 'DAGS_FOLDER/data_pipeline_dag.py', '--cfg-path', '/tmp/tmpezcqvcb5']
[2024-12-19T22:56:30.948+0000] {standard_task_runner.py:88} INFO - Job 191: Subtask data_processing_structured
[2024-12-19T22:56:31.000+0000] {task_command.py:423} INFO - Running <TaskInstance: data_pipeline.data_processing_structured manual__2024-12-19T22:56:27.030091+00:00 [running]> on host 1d3bd1c7da18
[2024-12-19T22:56:31.080+0000] {taskinstance.py:2480} INFO - Exporting env vars: AIRFLOW_CTX_DAG_OWNER='***' AIRFLOW_CTX_DAG_ID='data_pipeline' AIRFLOW_CTX_TASK_ID='data_processing_structured' AIRFLOW_CTX_EXECUTION_DATE='2024-12-19T22:56:27.030091+00:00' AIRFLOW_CTX_TRY_NUMBER='1' AIRFLOW_CTX_DAG_RUN_ID='manual__2024-12-19T22:56:27.030091+00:00'
[2024-12-19T22:56:31.579+0000] {taskinstance.py:2698} ERROR - Task failed with exception
Traceback (most recent call last):
  File "/home/airflow/.local/lib/python3.8/site-packages/airflow/models/taskinstance.py", line 433, in _execute_task
    result = execute_callable(context=context, **execute_callable_kwargs)
  File "/home/airflow/.local/lib/python3.8/site-packages/airflow/operators/python.py", line 199, in execute
    return_value = self.execute_callable()
  File "/home/airflow/.local/lib/python3.8/site-packages/airflow/operators/python.py", line 216, in execute_callable
    return self.python_callable(*self.op_args, **self.op_kwargs)
  File "/opt/airflow/dags/data_pipeline_dag.py", line 15, in trigger_api
    raise Exception(f"Error: {result['message']}")
Exception: Error: name 'session' is not defined
[2024-12-19T22:56:31.596+0000] {taskinstance.py:1138} INFO - Marking task as UP_FOR_RETRY. dag_id=data_pipeline, task_id=data_processing_structured, execution_date=20241219T225627, start_date=20241219T225630, end_date=20241219T225631
[2024-12-19T22:56:31.613+0000] {standard_task_runner.py:107} ERROR - Failed to execute job 191 for task data_processing_structured (Error: name 'session' is not defined; 23602)
[2024-12-19T22:56:31.641+0000] {local_task_job_runner.py:234} INFO - Task exited with return code 1
[2024-12-19T22:56:31.681+0000] {taskinstance.py:3280} INFO - 0 downstream tasks scheduled from follow-on schedule check
