[2024-12-20T15:27:28.665+0000] {taskinstance.py:1956} INFO - Dependencies all met for dep_context=non-requeueable deps ti=<TaskInstance: data_pipeline.data_ingestion manual__2024-12-20T15:27:25.348103+00:00 [queued]>
[2024-12-20T15:27:28.675+0000] {taskinstance.py:1956} INFO - Dependencies all met for dep_context=requeueable deps ti=<TaskInstance: data_pipeline.data_ingestion manual__2024-12-20T15:27:25.348103+00:00 [queued]>
[2024-12-20T15:27:28.676+0000] {taskinstance.py:2170} INFO - Starting attempt 1 of 3
[2024-12-20T15:27:28.694+0000] {taskinstance.py:2191} INFO - Executing <Task(PythonOperator): data_ingestion> on 2024-12-20 15:27:25.348103+00:00
[2024-12-20T15:27:28.701+0000] {standard_task_runner.py:60} INFO - Started process 644 to run task
[2024-12-20T15:27:28.704+0000] {standard_task_runner.py:87} INFO - Running: ['***', 'tasks', 'run', 'data_pipeline', 'data_ingestion', 'manual__2024-12-20T15:27:25.348103+00:00', '--job-id', '217', '--raw', '--subdir', 'DAGS_FOLDER/data_pipeline_dag.py', '--cfg-path', '/tmp/tmphv65y7fl']
[2024-12-20T15:27:28.707+0000] {standard_task_runner.py:88} INFO - Job 217: Subtask data_ingestion
[2024-12-20T15:27:28.764+0000] {task_command.py:423} INFO - Running <TaskInstance: data_pipeline.data_ingestion manual__2024-12-20T15:27:25.348103+00:00 [running]> on host 1d3bd1c7da18
[2024-12-20T15:27:28.858+0000] {taskinstance.py:2480} INFO - Exporting env vars: AIRFLOW_CTX_DAG_OWNER='***' AIRFLOW_CTX_DAG_ID='data_pipeline' AIRFLOW_CTX_TASK_ID='data_ingestion' AIRFLOW_CTX_EXECUTION_DATE='2024-12-20T15:27:25.348103+00:00' AIRFLOW_CTX_TRY_NUMBER='1' AIRFLOW_CTX_DAG_RUN_ID='manual__2024-12-20T15:27:25.348103+00:00'
[2024-12-20T15:27:30.928+0000] {taskinstance.py:2698} ERROR - Task failed with exception
Traceback (most recent call last):
  File "/home/airflow/.local/lib/python3.8/site-packages/urllib3/connection.py", line 174, in _new_conn
    conn = connection.create_connection(
  File "/home/airflow/.local/lib/python3.8/site-packages/urllib3/util/connection.py", line 95, in create_connection
    raise err
  File "/home/airflow/.local/lib/python3.8/site-packages/urllib3/util/connection.py", line 85, in create_connection
    sock.connect(sa)
ConnectionRefusedError: [Errno 111] Connection refused

During handling of the above exception, another exception occurred:

Traceback (most recent call last):
  File "/home/airflow/.local/lib/python3.8/site-packages/urllib3/connectionpool.py", line 715, in urlopen
    httplib_response = self._make_request(
  File "/home/airflow/.local/lib/python3.8/site-packages/urllib3/connectionpool.py", line 416, in _make_request
    conn.request(method, url, **httplib_request_kw)
  File "/home/airflow/.local/lib/python3.8/site-packages/urllib3/connection.py", line 244, in request
    super(HTTPConnection, self).request(method, url, body=body, headers=headers)
  File "/usr/local/lib/python3.8/http/client.py", line 1256, in request
    self._send_request(method, url, body, headers, encode_chunked)
  File "/usr/local/lib/python3.8/http/client.py", line 1302, in _send_request
    self.endheaders(body, encode_chunked=encode_chunked)
  File "/usr/local/lib/python3.8/http/client.py", line 1251, in endheaders
    self._send_output(message_body, encode_chunked=encode_chunked)
  File "/usr/local/lib/python3.8/http/client.py", line 1011, in _send_output
    self.send(msg)
  File "/usr/local/lib/python3.8/http/client.py", line 951, in send
    self.connect()
  File "/home/airflow/.local/lib/python3.8/site-packages/urllib3/connection.py", line 205, in connect
    conn = self._new_conn()
  File "/home/airflow/.local/lib/python3.8/site-packages/urllib3/connection.py", line 186, in _new_conn
    raise NewConnectionError(
urllib3.exceptions.NewConnectionError: <urllib3.connection.HTTPConnection object at 0x7fc7e233c700>: Failed to establish a new connection: [Errno 111] Connection refused

During handling of the above exception, another exception occurred:

Traceback (most recent call last):
  File "/home/airflow/.local/lib/python3.8/site-packages/requests/adapters.py", line 486, in send
    resp = conn.urlopen(
  File "/home/airflow/.local/lib/python3.8/site-packages/urllib3/connectionpool.py", line 799, in urlopen
    retries = retries.increment(
  File "/home/airflow/.local/lib/python3.8/site-packages/urllib3/util/retry.py", line 592, in increment
    raise MaxRetryError(_pool, url, error or ResponseError(cause))
urllib3.exceptions.MaxRetryError: HTTPConnectionPool(host='host.docker.internal', port=8000): Max retries exceeded with url: /run_script/data_ingestion (Caused by NewConnectionError('<urllib3.connection.HTTPConnection object at 0x7fc7e233c700>: Failed to establish a new connection: [Errno 111] Connection refused'))

During handling of the above exception, another exception occurred:

Traceback (most recent call last):
  File "/home/airflow/.local/lib/python3.8/site-packages/airflow/models/taskinstance.py", line 433, in _execute_task
    result = execute_callable(context=context, **execute_callable_kwargs)
  File "/home/airflow/.local/lib/python3.8/site-packages/airflow/operators/python.py", line 199, in execute
    return_value = self.execute_callable()
  File "/home/airflow/.local/lib/python3.8/site-packages/airflow/operators/python.py", line 216, in execute_callable
    return self.python_callable(*self.op_args, **self.op_kwargs)
  File "/opt/airflow/dags/data_pipeline_dag.py", line 9, in trigger_api
    response = requests.post(url)
  File "/home/airflow/.local/lib/python3.8/site-packages/requests/api.py", line 115, in post
    return request("post", url, data=data, json=json, **kwargs)
  File "/home/airflow/.local/lib/python3.8/site-packages/requests/api.py", line 59, in request
    return session.request(method=method, url=url, **kwargs)
  File "/home/airflow/.local/lib/python3.8/site-packages/requests/sessions.py", line 589, in request
    resp = self.send(prep, **send_kwargs)
  File "/home/airflow/.local/lib/python3.8/site-packages/requests/sessions.py", line 703, in send
    r = adapter.send(request, **kwargs)
  File "/home/airflow/.local/lib/python3.8/site-packages/requests/adapters.py", line 519, in send
    raise ConnectionError(e, request=request)
requests.exceptions.ConnectionError: HTTPConnectionPool(host='host.docker.internal', port=8000): Max retries exceeded with url: /run_script/data_ingestion (Caused by NewConnectionError('<urllib3.connection.HTTPConnection object at 0x7fc7e233c700>: Failed to establish a new connection: [Errno 111] Connection refused'))
[2024-12-20T15:27:30.944+0000] {taskinstance.py:1138} INFO - Marking task as UP_FOR_RETRY. dag_id=data_pipeline, task_id=data_ingestion, execution_date=20241220T152725, start_date=20241220T152728, end_date=20241220T152730
[2024-12-20T15:27:30.959+0000] {standard_task_runner.py:107} ERROR - Failed to execute job 217 for task data_ingestion (HTTPConnectionPool(host='host.docker.internal', port=8000): Max retries exceeded with url: /run_script/data_ingestion (Caused by NewConnectionError('<urllib3.connection.HTTPConnection object at 0x7fc7e233c700>: Failed to establish a new connection: [Errno 111] Connection refused')); 644)
[2024-12-20T15:27:31.006+0000] {local_task_job_runner.py:234} INFO - Task exited with return code 1
[2024-12-20T15:27:31.033+0000] {taskinstance.py:3280} INFO - 0 downstream tasks scheduled from follow-on schedule check
