[2024-12-18T18:00:42.522+0000] {taskinstance.py:1956} INFO - Dependencies all met for dep_context=non-requeueable deps ti=<TaskInstance: data_pipeline.save_to_postgresql manual__2024-12-18T18:00:40.927361+00:00 [queued]>
[2024-12-18T18:00:42.532+0000] {taskinstance.py:1956} INFO - Dependencies all met for dep_context=requeueable deps ti=<TaskInstance: data_pipeline.save_to_postgresql manual__2024-12-18T18:00:40.927361+00:00 [queued]>
[2024-12-18T18:00:42.532+0000] {taskinstance.py:2170} INFO - Starting attempt 1 of 2
[2024-12-18T18:00:42.552+0000] {taskinstance.py:2191} INFO - Executing <Task(PythonOperator): save_to_postgresql> on 2024-12-18 18:00:40.927361+00:00
[2024-12-18T18:00:42.559+0000] {standard_task_runner.py:60} INFO - Started process 201 to run task
[2024-12-18T18:00:42.562+0000] {standard_task_runner.py:87} INFO - Running: ['***', 'tasks', 'run', 'data_pipeline', 'save_to_postgresql', 'manual__2024-12-18T18:00:40.927361+00:00', '--job-id', '76', '--raw', '--subdir', 'DAGS_FOLDER/data_pipeline_dag.py', '--cfg-path', '/tmp/tmp_1us1483']
[2024-12-18T18:00:42.564+0000] {standard_task_runner.py:88} INFO - Job 76: Subtask save_to_postgresql
[2024-12-18T18:00:42.616+0000] {task_command.py:423} INFO - Running <TaskInstance: data_pipeline.save_to_postgresql manual__2024-12-18T18:00:40.927361+00:00 [running]> on host 1d3bd1c7da18
[2024-12-18T18:00:42.691+0000] {taskinstance.py:2480} INFO - Exporting env vars: AIRFLOW_CTX_DAG_OWNER='***' AIRFLOW_CTX_DAG_ID='data_pipeline' AIRFLOW_CTX_TASK_ID='save_to_postgresql' AIRFLOW_CTX_EXECUTION_DATE='2024-12-18T18:00:40.927361+00:00' AIRFLOW_CTX_TRY_NUMBER='1' AIRFLOW_CTX_DAG_RUN_ID='manual__2024-12-18T18:00:40.927361+00:00'
[2024-12-18T18:00:42.693+0000] {taskinstance.py:2698} ERROR - Task failed with exception
Traceback (most recent call last):
  File "/home/airflow/.local/lib/python3.8/site-packages/airflow/models/taskinstance.py", line 433, in _execute_task
    result = execute_callable(context=context, **execute_callable_kwargs)
  File "/home/airflow/.local/lib/python3.8/site-packages/airflow/operators/python.py", line 199, in execute
    return_value = self.execute_callable()
  File "/home/airflow/.local/lib/python3.8/site-packages/airflow/operators/python.py", line 216, in execute_callable
    return self.python_callable(*self.op_args, **self.op_kwargs)
  File "/opt/airflow/dags/data_pipeline_dag.py", line 31, in save_to_postgresql
    conn = psycopg2.connect(
  File "/home/airflow/.local/lib/python3.8/site-packages/psycopg2/__init__.py", line 122, in connect
    conn = _connect(dsn, connection_factory=connection_factory, **kwasync)
psycopg2.OperationalError: connection to server at "localhost" (127.0.0.1), port 5431 failed: Connection refused
	Is the server running on that host and accepting TCP/IP connections?
connection to server at "localhost" (::1), port 5431 failed: Cannot assign requested address
	Is the server running on that host and accepting TCP/IP connections?

[2024-12-18T18:00:42.704+0000] {taskinstance.py:1138} INFO - Marking task as UP_FOR_RETRY. dag_id=data_pipeline, task_id=save_to_postgresql, execution_date=20241218T180040, start_date=20241218T180042, end_date=20241218T180042
[2024-12-18T18:00:42.717+0000] {standard_task_runner.py:107} ERROR - Failed to execute job 76 for task save_to_postgresql (connection to server at "localhost" (127.0.0.1), port 5431 failed: Connection refused
	Is the server running on that host and accepting TCP/IP connections?
connection to server at "localhost" (::1), port 5431 failed: Cannot assign requested address
	Is the server running on that host and accepting TCP/IP connections?
; 201)
[2024-12-18T18:00:42.736+0000] {local_task_job_runner.py:234} INFO - Task exited with return code 1
[2024-12-18T18:00:42.754+0000] {taskinstance.py:3280} INFO - 0 downstream tasks scheduled from follow-on schedule check
