[2024-12-17T07:12:57.142+0000] {taskinstance.py:1956} INFO - Dependencies all met for dep_context=non-requeueable deps ti=<TaskInstance: data_pipeline.save_to_postgresql manual__2024-12-17T07:12:48.765838+00:00 [queued]>
[2024-12-17T07:12:57.151+0000] {taskinstance.py:1956} INFO - Dependencies all met for dep_context=requeueable deps ti=<TaskInstance: data_pipeline.save_to_postgresql manual__2024-12-17T07:12:48.765838+00:00 [queued]>
[2024-12-17T07:12:57.152+0000] {taskinstance.py:2170} INFO - Starting attempt 1 of 2
[2024-12-17T07:12:57.170+0000] {taskinstance.py:2191} INFO - Executing <Task(PythonOperator): save_to_postgresql> on 2024-12-17 07:12:48.765838+00:00
[2024-12-17T07:12:57.176+0000] {standard_task_runner.py:60} INFO - Started process 577 to run task
[2024-12-17T07:12:57.179+0000] {standard_task_runner.py:87} INFO - Running: ['***', 'tasks', 'run', 'data_pipeline', 'save_to_postgresql', 'manual__2024-12-17T07:12:48.765838+00:00', '--job-id', '11', '--raw', '--subdir', 'DAGS_FOLDER/data_pipeline_dag.py', '--cfg-path', '/tmp/tmp3zoflk_m']
[2024-12-17T07:12:57.181+0000] {standard_task_runner.py:88} INFO - Job 11: Subtask save_to_postgresql
[2024-12-17T07:12:57.231+0000] {task_command.py:423} INFO - Running <TaskInstance: data_pipeline.save_to_postgresql manual__2024-12-17T07:12:48.765838+00:00 [running]> on host 61bab220abc0
[2024-12-17T07:12:57.317+0000] {taskinstance.py:2480} INFO - Exporting env vars: AIRFLOW_CTX_DAG_OWNER='***' AIRFLOW_CTX_DAG_ID='data_pipeline' AIRFLOW_CTX_TASK_ID='save_to_postgresql' AIRFLOW_CTX_EXECUTION_DATE='2024-12-17T07:12:48.765838+00:00' AIRFLOW_CTX_TRY_NUMBER='1' AIRFLOW_CTX_DAG_RUN_ID='manual__2024-12-17T07:12:48.765838+00:00'
[2024-12-17T07:12:57.319+0000] {taskinstance.py:2698} ERROR - Task failed with exception
Traceback (most recent call last):
  File "/home/airflow/.local/lib/python3.8/site-packages/airflow/models/taskinstance.py", line 433, in _execute_task
    result = execute_callable(context=context, **execute_callable_kwargs)
  File "/home/airflow/.local/lib/python3.8/site-packages/airflow/operators/python.py", line 199, in execute
    return_value = self.execute_callable()
  File "/home/airflow/.local/lib/python3.8/site-packages/airflow/operators/python.py", line 216, in execute_callable
    return self.python_callable(*self.op_args, **self.op_kwargs)
  File "/opt/airflow/dags/data_pipeline_dag.py", line 26, in save_to_postgresql
    conn = psycopg2.connect(
  File "/home/airflow/.local/lib/python3.8/site-packages/psycopg2/__init__.py", line 122, in connect
    conn = _connect(dsn, connection_factory=connection_factory, **kwasync)
psycopg2.OperationalError: connection to server at "localhost" (127.0.0.1), port 5431 failed: Connection refused
	Is the server running on that host and accepting TCP/IP connections?
connection to server at "localhost" (::1), port 5431 failed: Cannot assign requested address
	Is the server running on that host and accepting TCP/IP connections?

[2024-12-17T07:12:57.331+0000] {taskinstance.py:1138} INFO - Marking task as UP_FOR_RETRY. dag_id=data_pipeline, task_id=save_to_postgresql, execution_date=20241217T071248, start_date=20241217T071257, end_date=20241217T071257
[2024-12-17T07:12:57.344+0000] {standard_task_runner.py:107} ERROR - Failed to execute job 11 for task save_to_postgresql (connection to server at "localhost" (127.0.0.1), port 5431 failed: Connection refused
	Is the server running on that host and accepting TCP/IP connections?
connection to server at "localhost" (::1), port 5431 failed: Cannot assign requested address
	Is the server running on that host and accepting TCP/IP connections?
; 577)
[2024-12-17T07:12:57.393+0000] {local_task_job_runner.py:234} INFO - Task exited with return code 1
[2024-12-17T07:12:57.409+0000] {taskinstance.py:3280} INFO - 0 downstream tasks scheduled from follow-on schedule check
