[2024-12-19T14:36:05.239+0000] {taskinstance.py:1956} INFO - Dependencies all met for dep_context=non-requeueable deps ti=<TaskInstance: data_pipeline.data_ingestion manual__2024-12-19T14:36:02.790798+00:00 [queued]>
[2024-12-19T14:36:05.248+0000] {taskinstance.py:1956} INFO - Dependencies all met for dep_context=requeueable deps ti=<TaskInstance: data_pipeline.data_ingestion manual__2024-12-19T14:36:02.790798+00:00 [queued]>
[2024-12-19T14:36:05.249+0000] {taskinstance.py:2170} INFO - Starting attempt 1 of 2
[2024-12-19T14:36:05.267+0000] {taskinstance.py:2191} INFO - Executing <Task(PythonOperator): data_ingestion> on 2024-12-19 14:36:02.790798+00:00
[2024-12-19T14:36:05.273+0000] {standard_task_runner.py:60} INFO - Started process 16064 to run task
[2024-12-19T14:36:05.276+0000] {standard_task_runner.py:87} INFO - Running: ['***', 'tasks', 'run', 'data_pipeline', 'data_ingestion', 'manual__2024-12-19T14:36:02.790798+00:00', '--job-id', '140', '--raw', '--subdir', 'DAGS_FOLDER/data_pipeline_dag.py', '--cfg-path', '/tmp/tmp14eo1xh6']
[2024-12-19T14:36:05.278+0000] {standard_task_runner.py:88} INFO - Job 140: Subtask data_ingestion
[2024-12-19T14:36:05.333+0000] {task_command.py:423} INFO - Running <TaskInstance: data_pipeline.data_ingestion manual__2024-12-19T14:36:02.790798+00:00 [running]> on host 1d3bd1c7da18
[2024-12-19T14:36:05.422+0000] {taskinstance.py:2480} INFO - Exporting env vars: AIRFLOW_CTX_DAG_OWNER='***' AIRFLOW_CTX_DAG_ID='data_pipeline' AIRFLOW_CTX_TASK_ID='data_ingestion' AIRFLOW_CTX_EXECUTION_DATE='2024-12-19T14:36:02.790798+00:00' AIRFLOW_CTX_TRY_NUMBER='1' AIRFLOW_CTX_DAG_RUN_ID='manual__2024-12-19T14:36:02.790798+00:00'
[2024-12-19T14:36:05.472+0000] {taskinstance.py:2698} ERROR - Task failed with exception
Traceback (most recent call last):
  File "/home/airflow/.local/lib/python3.8/site-packages/airflow/models/taskinstance.py", line 433, in _execute_task
    result = execute_callable(context=context, **execute_callable_kwargs)
  File "/home/airflow/.local/lib/python3.8/site-packages/airflow/operators/python.py", line 199, in execute
    return_value = self.execute_callable()
  File "/home/airflow/.local/lib/python3.8/site-packages/airflow/operators/python.py", line 216, in execute_callable
    return self.python_callable(*self.op_args, **self.op_kwargs)
  File "/opt/airflow/dags/data_pipeline_dag.py", line 15, in trigger_api
    raise Exception(f"Error: {result['message']}")
Exception: Error: Script data_ingestion failed
[2024-12-19T14:36:05.485+0000] {taskinstance.py:1138} INFO - Marking task as UP_FOR_RETRY. dag_id=data_pipeline, task_id=data_ingestion, execution_date=20241219T143602, start_date=20241219T143605, end_date=20241219T143605
[2024-12-19T14:36:05.502+0000] {standard_task_runner.py:107} ERROR - Failed to execute job 140 for task data_ingestion (Error: Script data_ingestion failed; 16064)
[2024-12-19T14:36:05.529+0000] {local_task_job_runner.py:234} INFO - Task exited with return code 1
[2024-12-19T14:36:05.560+0000] {taskinstance.py:3280} INFO - 0 downstream tasks scheduled from follow-on schedule check
