[2024-12-17T08:23:24.794+0000] {taskinstance.py:1956} INFO - Dependencies all met for dep_context=non-requeueable deps ti=<TaskInstance: data_pipeline.data_ingestion manual__2024-12-17T08:23:22.981890+00:00 [queued]>
[2024-12-17T08:23:24.802+0000] {taskinstance.py:1956} INFO - Dependencies all met for dep_context=requeueable deps ti=<TaskInstance: data_pipeline.data_ingestion manual__2024-12-17T08:23:22.981890+00:00 [queued]>
[2024-12-17T08:23:24.803+0000] {taskinstance.py:2170} INFO - Starting attempt 1 of 2
[2024-12-17T08:23:24.819+0000] {taskinstance.py:2191} INFO - Executing <Task(PythonOperator): data_ingestion> on 2024-12-17 08:23:22.981890+00:00
[2024-12-17T08:23:24.825+0000] {standard_task_runner.py:60} INFO - Started process 82 to run task
[2024-12-17T08:23:24.827+0000] {standard_task_runner.py:87} INFO - Running: ['***', 'tasks', 'run', 'data_pipeline', 'data_ingestion', 'manual__2024-12-17T08:23:22.981890+00:00', '--job-id', '33', '--raw', '--subdir', 'DAGS_FOLDER/data_pipeline_dag.py', '--cfg-path', '/tmp/tmpqxxuflj9']
[2024-12-17T08:23:24.830+0000] {standard_task_runner.py:88} INFO - Job 33: Subtask data_ingestion
[2024-12-17T08:23:24.879+0000] {task_command.py:423} INFO - Running <TaskInstance: data_pipeline.data_ingestion manual__2024-12-17T08:23:22.981890+00:00 [running]> on host 1d3bd1c7da18
[2024-12-17T08:23:24.954+0000] {taskinstance.py:2480} INFO - Exporting env vars: AIRFLOW_CTX_DAG_OWNER='***' AIRFLOW_CTX_DAG_ID='data_pipeline' AIRFLOW_CTX_TASK_ID='data_ingestion' AIRFLOW_CTX_EXECUTION_DATE='2024-12-17T08:23:22.981890+00:00' AIRFLOW_CTX_TRY_NUMBER='1' AIRFLOW_CTX_DAG_RUN_ID='manual__2024-12-17T08:23:22.981890+00:00'
[2024-12-17T08:23:24.956+0000] {logging_mixin.py:188} INFO - Data ingestion starting
[2024-12-17T08:23:24.957+0000] {taskinstance.py:2698} ERROR - Task failed with exception
Traceback (most recent call last):
  File "/home/airflow/.local/lib/python3.8/site-packages/airflow/models/taskinstance.py", line 433, in _execute_task
    result = execute_callable(context=context, **execute_callable_kwargs)
  File "/home/airflow/.local/lib/python3.8/site-packages/airflow/operators/python.py", line 199, in execute
    return_value = self.execute_callable()
  File "/home/airflow/.local/lib/python3.8/site-packages/airflow/operators/python.py", line 216, in execute_callable
    return self.python_callable(*self.op_args, **self.op_kwargs)
  File "/opt/airflow/dags/data_pipeline_dag.py", line 10, in data_ingestion
    print(os.cwd())
AttributeError: module 'os' has no attribute 'cwd'
[2024-12-17T08:23:24.968+0000] {taskinstance.py:1138} INFO - Marking task as UP_FOR_RETRY. dag_id=data_pipeline, task_id=data_ingestion, execution_date=20241217T082322, start_date=20241217T082324, end_date=20241217T082324
[2024-12-17T08:23:24.982+0000] {standard_task_runner.py:107} ERROR - Failed to execute job 33 for task data_ingestion (module 'os' has no attribute 'cwd'; 82)
[2024-12-17T08:23:25.000+0000] {local_task_job_runner.py:234} INFO - Task exited with return code 1
[2024-12-17T08:23:25.024+0000] {taskinstance.py:3280} INFO - 0 downstream tasks scheduled from follow-on schedule check
