[2024-12-18T22:24:26.100+0000] {taskinstance.py:1956} INFO - Dependencies all met for dep_context=non-requeueable deps ti=<TaskInstance: data_pipeline.env_preparation manual__2024-12-18T22:24:24.526892+00:00 [queued]>
[2024-12-18T22:24:26.109+0000] {taskinstance.py:1956} INFO - Dependencies all met for dep_context=requeueable deps ti=<TaskInstance: data_pipeline.env_preparation manual__2024-12-18T22:24:24.526892+00:00 [queued]>
[2024-12-18T22:24:26.110+0000] {taskinstance.py:2170} INFO - Starting attempt 1 of 2
[2024-12-18T22:24:26.126+0000] {taskinstance.py:2191} INFO - Executing <Task(PythonOperator): env_preparation> on 2024-12-18 22:24:24.526892+00:00
[2024-12-18T22:24:26.134+0000] {standard_task_runner.py:60} INFO - Started process 1465 to run task
[2024-12-18T22:24:26.137+0000] {standard_task_runner.py:87} INFO - Running: ['***', 'tasks', 'run', 'data_pipeline', 'env_preparation', 'manual__2024-12-18T22:24:24.526892+00:00', '--job-id', '117', '--raw', '--subdir', 'DAGS_FOLDER/data_pipeline_dag.py', '--cfg-path', '/tmp/tmpsntgv9i9']
[2024-12-18T22:24:26.139+0000] {standard_task_runner.py:88} INFO - Job 117: Subtask env_preparation
[2024-12-18T22:24:26.194+0000] {task_command.py:423} INFO - Running <TaskInstance: data_pipeline.env_preparation manual__2024-12-18T22:24:24.526892+00:00 [running]> on host 1d3bd1c7da18
[2024-12-18T22:24:26.280+0000] {taskinstance.py:2480} INFO - Exporting env vars: AIRFLOW_CTX_DAG_OWNER='***' AIRFLOW_CTX_DAG_ID='data_pipeline' AIRFLOW_CTX_TASK_ID='env_preparation' AIRFLOW_CTX_EXECUTION_DATE='2024-12-18T22:24:24.526892+00:00' AIRFLOW_CTX_TRY_NUMBER='1' AIRFLOW_CTX_DAG_RUN_ID='manual__2024-12-18T22:24:24.526892+00:00'
[2024-12-18T22:24:26.283+0000] {taskinstance.py:2698} ERROR - Task failed with exception
Traceback (most recent call last):
  File "/home/airflow/.local/lib/python3.8/site-packages/airflow/models/taskinstance.py", line 433, in _execute_task
    result = execute_callable(context=context, **execute_callable_kwargs)
  File "/home/airflow/.local/lib/python3.8/site-packages/airflow/operators/python.py", line 199, in execute
    return_value = self.execute_callable()
  File "/home/airflow/.local/lib/python3.8/site-packages/airflow/operators/python.py", line 216, in execute_callable
    return self.python_callable(*self.op_args, **self.op_kwargs)
  File "/opt/airflow/dags/data_pipeline_dag.py", line 9, in env_preparation
    os.system(os.listdir(os.getcwd())+" >> mylogt.txt")
TypeError: can only concatenate list (not "str") to list
[2024-12-18T22:24:26.294+0000] {taskinstance.py:1138} INFO - Marking task as UP_FOR_RETRY. dag_id=data_pipeline, task_id=env_preparation, execution_date=20241218T222424, start_date=20241218T222426, end_date=20241218T222426
[2024-12-18T22:24:26.308+0000] {standard_task_runner.py:107} ERROR - Failed to execute job 117 for task env_preparation (can only concatenate list (not "str") to list; 1465)
[2024-12-18T22:24:26.349+0000] {local_task_job_runner.py:234} INFO - Task exited with return code 1
[2024-12-18T22:24:26.374+0000] {taskinstance.py:3280} INFO - 0 downstream tasks scheduled from follow-on schedule check
